1. 【强制】【umijs/lint】try...catch 捕获的错误不能重新赋值。eslint：[no-ex-assign](https://eslint.org/docs/latest/rules/no-ex-assign)；

- <Badge type="error">BAD</Badge>

```jsx | pure
try {
  // 一些代码
} catch (err) {
  err = new Error('新的错误对象'); // 重新赋值错误对象
  console.error(err);
}
```

- <Badge type="success">GOOD</Badge>

```jsx | pure
try {
  // 一些代码
} catch (err) {
  console.error(err);
}
```

2. 【强制】【umijs/lint】catch 不能直接使用 throw 抛出错误，这时 catch 不必要。eslint：[no-useless-catch](https://eslint.org/docs/latest/rules/no-useless-catch)；

- <Badge type="error">BAD</Badge>

```jsx | pure
try {
  // 一些代码
} catch (err) {
  throw err; // 直接抛出错误
}
```

在上述代码中，catch 块内部没有对错误进行任何处理，直接通过 throw 语句抛出错误。这种情况下，catch 块实际上是多余的，可以直接省略。

为了修复这个问题，应该删除不必要的 catch 块，直接在 try 块中抛出错误或者在 catch 块中对错误进行实际的处理。

- <Badge type="success">GOOD</Badge>

```jsx | pure
try {
  // 一些代码
  throw new Error('错误信息'); // 直接在 try 块中抛出错误
} catch (err) {
  console.error(err); // 对错误进行实际处理
}
```

3. 【推荐】【umijs/lint】finally 内不能包含 return、throw、break、continue 等控制语句。因为在执行 try、catch 内的同类语句前，js 会先执行 finally 中的，这就会导致预期之外的 return 等情况发生。eslint：[no-unsafe-finally](https://eslint.org/docs/latest/rules/no-unsafe-finally)；

- <Badge type="error">BAD</Badge>

```jsx | pure
function foo() {
  try {
    return 1;
  } catch (err) {
    // 捕获异常
  } finally {
    throw new Error('错误'); // 在 finally 中抛出错误
  }
}
```

在上述代码中，finally 块中使用 throw 抛出了一个错误。这会导致在 finally 块中抛出的错误优先于 try 块中的 return 语句执行，最终导致函数返回了一个错误，而不是预期的值。这种情况可能会引起意外的行为，因为 finally 块中的代码会在 return 之后执行。

为了修复这个问题，应该避免在 finally 块中包含可能导致意外行为的控制语句。如果需要在 finally 块中执行一些清理操作或释放资源，应该确保这些操作不会影响函数的返回值或引发意外的行为。

- <Badge type="success">GOOD</Badge>

```jsx | pure
function foo() {
  try {
    return 1;
  } catch (err) {
    // 捕获异常
  } finally {
    // 执行一些清理操作或释放资源
  }
}
```
